2020-09-11 03:30:54,200 ERROR: Exception on /page_res_issue [GET] [in /home/kr/miniconda3/envs/mybc/lib/python3.7/site-packages/flask/app.py:1892]
Traceback (most recent call last):
  File "/home/kr/miniconda3/envs/mybc/lib/python3.7/site-packages/sqlalchemy/orm/base.py", line 399, in _entity_descriptor
    return getattr(entity, key)
AttributeError: type object 'Certs' has no attribute 'transfer_id'

During handling of the above exception, another exception occurred:

Traceback (most recent call last):
  File "/home/kr/miniconda3/envs/mybc/lib/python3.7/site-packages/flask/app.py", line 2447, in wsgi_app
    response = self.full_dispatch_request()
  File "/home/kr/miniconda3/envs/mybc/lib/python3.7/site-packages/flask/app.py", line 1952, in full_dispatch_request
    rv = self.handle_user_exception(e)
  File "/home/kr/miniconda3/envs/mybc/lib/python3.7/site-packages/flask/app.py", line 1821, in handle_user_exception
    reraise(exc_type, exc_value, tb)
  File "/home/kr/miniconda3/envs/mybc/lib/python3.7/site-packages/flask/_compat.py", line 39, in reraise
    raise value
  File "/home/kr/miniconda3/envs/mybc/lib/python3.7/site-packages/flask/app.py", line 1950, in full_dispatch_request
    rv = self.dispatch_request()
  File "/home/kr/miniconda3/envs/mybc/lib/python3.7/site-packages/flask/app.py", line 1936, in dispatch_request
    return self.view_functions[rule.endpoint](**req.view_args)
  File "/home/kr/miniconda3/envs/mybc/lib/python3.7/site-packages/flask_login/utils.py", line 261, in decorated_view
    return func(*args, **kwargs)
  File "/home/kr/workspace/ElectronicData/app/routes.py", line 341, in page_res_issue
    resources=resources
  File "/home/kr/miniconda3/envs/mybc/lib/python3.7/site-packages/flask/templating.py", line 140, in render_template
    ctx.app,
  File "/home/kr/miniconda3/envs/mybc/lib/python3.7/site-packages/flask/templating.py", line 120, in _render
    rv = template.render(context)
  File "/home/kr/miniconda3/envs/mybc/lib/python3.7/site-packages/jinja2/asyncsupport.py", line 76, in render
    return original_render(self, *args, **kwargs)
  File "/home/kr/miniconda3/envs/mybc/lib/python3.7/site-packages/jinja2/environment.py", line 1008, in render
    return self.environment.handle_exception(exc_info, True)
  File "/home/kr/miniconda3/envs/mybc/lib/python3.7/site-packages/jinja2/environment.py", line 780, in handle_exception
    reraise(exc_type, exc_value, tb)
  File "/home/kr/miniconda3/envs/mybc/lib/python3.7/site-packages/jinja2/_compat.py", line 37, in reraise
    raise value.with_traceback(tb)
  File "/home/kr/workspace/ElectronicData/app/templates/myres/res_issue.html", line 1, in top-level template code
    {% extends "base/base.html" %}
  File "/home/kr/miniconda3/envs/mybc/lib/python3.7/site-packages/jinja2/environment.py", line 1005, in render
    return concat(self.root_render_func(self.new_context(vars)))
  File "/home/kr/workspace/ElectronicData/app/templates/myres/res_issue.html", line 14, in root
  File "/home/kr/workspace/ElectronicData/app/templates/base/base.html", line 80, in root
    "timeOut": "5000",
  File "/home/kr/workspace/ElectronicData/app/templates/myres/res_issue.html", line 51, in block_content
    </div>
  File "/home/kr/miniconda3/envs/mybc/lib/python3.7/site-packages/jinja2/runtime.py", line 262, in call
    return __obj(*args, **kwargs)
  File "/home/kr/workspace/ElectronicData/app/models.py", line 82, in paid_nums
    transfer_id=None
  File "/home/kr/miniconda3/envs/mybc/lib/python3.7/site-packages/sqlalchemy/orm/query.py", line 1800, in filter_by
    for key, value in kwargs.items()
  File "/home/kr/miniconda3/envs/mybc/lib/python3.7/site-packages/sqlalchemy/orm/query.py", line 1800, in <listcomp>
    for key, value in kwargs.items()
  File "/home/kr/miniconda3/envs/mybc/lib/python3.7/site-packages/sqlalchemy/orm/base.py", line 402, in _entity_descriptor
    "Entity '%s' has no property '%s'" % (description, key)
sqlalchemy.exc.InvalidRequestError: Entity '<class 'app.models.Certs'>' has no property 'transfer_id'
2020-09-11 03:31:03,509 ERROR: Exception on /page_res_issue [GET] [in /home/kr/miniconda3/envs/mybc/lib/python3.7/site-packages/flask/app.py:1892]
Traceback (most recent call last):
  File "/home/kr/miniconda3/envs/mybc/lib/python3.7/site-packages/sqlalchemy/orm/base.py", line 399, in _entity_descriptor
    return getattr(entity, key)
AttributeError: type object 'Certs' has no attribute 'transfer_id'

During handling of the above exception, another exception occurred:

Traceback (most recent call last):
  File "/home/kr/miniconda3/envs/mybc/lib/python3.7/site-packages/flask/app.py", line 2447, in wsgi_app
    response = self.full_dispatch_request()
  File "/home/kr/miniconda3/envs/mybc/lib/python3.7/site-packages/flask/app.py", line 1952, in full_dispatch_request
    rv = self.handle_user_exception(e)
  File "/home/kr/miniconda3/envs/mybc/lib/python3.7/site-packages/flask/app.py", line 1821, in handle_user_exception
    reraise(exc_type, exc_value, tb)
  File "/home/kr/miniconda3/envs/mybc/lib/python3.7/site-packages/flask/_compat.py", line 39, in reraise
    raise value
  File "/home/kr/miniconda3/envs/mybc/lib/python3.7/site-packages/flask/app.py", line 1950, in full_dispatch_request
    rv = self.dispatch_request()
  File "/home/kr/miniconda3/envs/mybc/lib/python3.7/site-packages/flask/app.py", line 1936, in dispatch_request
    return self.view_functions[rule.endpoint](**req.view_args)
  File "/home/kr/miniconda3/envs/mybc/lib/python3.7/site-packages/flask_login/utils.py", line 261, in decorated_view
    return func(*args, **kwargs)
  File "/home/kr/workspace/ElectronicData/app/routes.py", line 341, in page_res_issue
    resources=resources
  File "/home/kr/miniconda3/envs/mybc/lib/python3.7/site-packages/flask/templating.py", line 140, in render_template
    ctx.app,
  File "/home/kr/miniconda3/envs/mybc/lib/python3.7/site-packages/flask/templating.py", line 120, in _render
    rv = template.render(context)
  File "/home/kr/miniconda3/envs/mybc/lib/python3.7/site-packages/jinja2/asyncsupport.py", line 76, in render
    return original_render(self, *args, **kwargs)
  File "/home/kr/miniconda3/envs/mybc/lib/python3.7/site-packages/jinja2/environment.py", line 1008, in render
    return self.environment.handle_exception(exc_info, True)
  File "/home/kr/miniconda3/envs/mybc/lib/python3.7/site-packages/jinja2/environment.py", line 780, in handle_exception
    reraise(exc_type, exc_value, tb)
  File "/home/kr/miniconda3/envs/mybc/lib/python3.7/site-packages/jinja2/_compat.py", line 37, in reraise
    raise value.with_traceback(tb)
  File "/home/kr/workspace/ElectronicData/app/templates/myres/res_issue.html", line 1, in top-level template code
    {% extends "base/base.html" %}
  File "/home/kr/miniconda3/envs/mybc/lib/python3.7/site-packages/jinja2/environment.py", line 1005, in render
    return concat(self.root_render_func(self.new_context(vars)))
  File "/home/kr/workspace/ElectronicData/app/templates/myres/res_issue.html", line 14, in root
  File "/home/kr/workspace/ElectronicData/app/templates/base/base.html", line 80, in root
    "timeOut": "5000",
  File "/home/kr/workspace/ElectronicData/app/templates/myres/res_issue.html", line 51, in block_content
    </div>
  File "/home/kr/miniconda3/envs/mybc/lib/python3.7/site-packages/jinja2/runtime.py", line 262, in call
    return __obj(*args, **kwargs)
  File "/home/kr/workspace/ElectronicData/app/models.py", line 82, in paid_nums
    transfer_id=None
  File "/home/kr/miniconda3/envs/mybc/lib/python3.7/site-packages/sqlalchemy/orm/query.py", line 1800, in filter_by
    for key, value in kwargs.items()
  File "/home/kr/miniconda3/envs/mybc/lib/python3.7/site-packages/sqlalchemy/orm/query.py", line 1800, in <listcomp>
    for key, value in kwargs.items()
  File "/home/kr/miniconda3/envs/mybc/lib/python3.7/site-packages/sqlalchemy/orm/base.py", line 402, in _entity_descriptor
    "Entity '%s' has no property '%s'" % (description, key)
sqlalchemy.exc.InvalidRequestError: Entity '<class 'app.models.Certs'>' has no property 'transfer_id'
